<?xml version="1.0" encoding="utf-8"?>
<!-- =================================================================================== -->
<!-- |    This document was autogenerated by xacro from elfin10.urdf.xacro             | -->
<!-- |    EDITING THIS FILE BY HAND IS NOT RECOMMENDED                                 | -->
<!-- =================================================================================== -->
<robot name="elfin10">
  <material name="black">
    <color rgba="0.0 0.0 0.0 1.0"/>
  </material>
  <material name="blue">
    <color rgba="0.0 0.0 0.8 1.0"/>
  </material>
  <material name="green">
    <color rgba="0.0 0.8 0.0 1.0"/>
  </material>
  <material name="grey">
    <color rgba="0.2 0.2 0.2 1.0"/>
  </material>
  <material name="orange">
    <color rgba="1.0 0.423529411765 0.0392156862745 1.0"/>
  </material>
  <material name="brown">
    <color rgba="0.870588235294 0.811764705882 0.764705882353 1.0"/>
  </material>
  <material name="red">
    <color rgba="0.8 0.0 0.0 1.0"/>
  </material>
  <material name="white">
    <color rgba="1.0 1.0 1.0 1.0"/>
  </material>
  <material name="metal">
    <color rgba="0.768627450980392 0.749019607843137 0.729411764705882 1"/>
  </material>
  <material name="metal_grey">
    <color rgba="0.501960784313725 0.501960784313725 0.501960784313725 1"/>
  </material>
  <material name="metal_white">
    <color rgba="0.866666666666667 0.866666666666667 0.890196078431373 1"/>
  </material>
  <!-- ros_control plugin -->
  <gazebo>
    <plugin filename="libgazebo_ros_control.so" name="gazebo_ros_control">
      <robotSimType>gazebo_ros_control/DefaultRobotHWSim</robotSimType>
      <legacyModeNS>true</legacyModeNS>
    </plugin>
  </gazebo>
  <gazebo reference="elfin_link2">
    <visual name="visual">
      <material>
        <script>
          <uri>file://media/materials/scripts/gazebo.material</uri>
          <name>Gazebo/Grey</name>
        </script>
      </material>
    </visual>
  </gazebo>
  <gazebo reference="elfin_link4">
    <visual name="visual">
      <material>
        <script>
          <uri>file://media/materials/scripts/gazebo.material</uri>
          <name>Gazebo/Grey</name>
        </script>
      </material>
    </visual>
  </gazebo>
  <transmission name="elfin_joint1_trans">
    <type>transmission_interface/SimpleTransmission</type>
    <joint name="elfin_joint1">
      <hardwareInterface>hardware_interface/PositionJointInterface</hardwareInterface>
    </joint>
    <actuator name="elfin_joint1_motor">
      <mechanicalReduction>1</mechanicalReduction>
    </actuator>
  </transmission>
  <transmission name="elfin_joint2_trans">
    <type>transmission_interface/SimpleTransmission</type>
    <joint name="elfin_joint2">
      <hardwareInterface>hardware_interface/PositionJointInterface</hardwareInterface>
    </joint>
    <actuator name="elfin_joint2_motor">
      <mechanicalReduction>1</mechanicalReduction>
    </actuator>
  </transmission>
  <transmission name="elfin_joint3_trans">
    <type>transmission_interface/SimpleTransmission</type>
    <joint name="elfin_joint3">
      <hardwareInterface>hardware_interface/PositionJointInterface</hardwareInterface>
    </joint>
    <actuator name="elfin_joint3_motor">
      <mechanicalReduction>1</mechanicalReduction>
    </actuator>
  </transmission>
  <transmission name="elfin_joint4_trans">
    <type>transmission_interface/SimpleTransmission</type>
    <joint name="elfin_joint4">
      <hardwareInterface>hardware_interface/PositionJointInterface</hardwareInterface>
    </joint>
    <actuator name="elfin_joint4_motor">
      <mechanicalReduction>1</mechanicalReduction>
    </actuator>
  </transmission>
  <transmission name="elfin_joint5_trans">
    <type>transmission_interface/SimpleTransmission</type>
    <joint name="elfin_joint5">
      <hardwareInterface>hardware_interface/PositionJointInterface</hardwareInterface>
    </joint>
    <actuator name="elfin_joint5_motor">
      <mechanicalReduction>1</mechanicalReduction>
    </actuator>
  </transmission>
  <transmission name="elfin_joint6_trans">
    <type>transmission_interface/SimpleTransmission</type>
    <joint name="elfin_joint6">
      <hardwareInterface>hardware_interface/PositionJointInterface</hardwareInterface>
    </joint>
    <actuator name="elfin_joint6_motor">
      <mechanicalReduction>1</mechanicalReduction>
    </actuator>
  </transmission>
  <link name="world"/>
  <joint name="world_base" type="fixed">
    <origin rpy="0 0 -1.5708" xyz="0 0 0"/>
    <parent link="world"/>
    <child link="elfin_base_link"/>
  </joint>
  <link name="elfin_base_link"/>
  <joint name="elfin_base_joint" type="fixed">
    <origin rpy="0 0 1.57079632679" xyz="0 0 0"/>
    <parent link="elfin_base_link"/>
    <child link="elfin_base"/>
  </joint>
  <link name="elfin_base">
    <inertial>
      <origin rpy="0 0 0" xyz="-0.00272891148525253 0.000307855470977014 0.0272857003429058"/>
      <mass value="0.885322892252566"/>
      <inertia ixx="0.00301072999783137" ixy="-1.61177742996604E-05" ixz="-3.9001744857601E-05" iyy="0.0026859684784965" iyz="3.74127558541537E-06" izz="0.00520484836475965"/>
    </inertial>
    <visual>
      <origin rpy="0 0 0" xyz="0 0 0"/>
      <geometry>
        <mesh filename="package://elfin_description/meshes/elfin10/elfin_base_link.STL"/>
      </geometry>
      <material name="">
        <color rgba="0.792156862745098 0.819607843137255 0.929411764705882 1"/>
      </material>
    </visual>
    <collision>
      <origin rpy="0 0 0" xyz="0 0 0"/>
      <geometry>
        <mesh filename="package://elfin_description/meshes/elfin10/elfin_base_link.STL"/>
      </geometry>
    </collision>
  </link>
  <link name="elfin_link1">
    <inertial>
      <origin rpy="0 0 0" xyz="1.64450419081555E-05 -0.0256037445106889 0.116231470679274"/>
      <mass value="5.06676664437865"/>
      <inertia ixx="0.0432021422624639" ixy="-5.87315615826586E-06" ixz="-3.3817285662756E-06" iyy="0.0389769463442445" iyz="0.00975755293023606" izz="0.0198084067505502"/>
    </inertial>
    <visual>
      <origin rpy="0 0 0" xyz="0 0 0"/>
      <geometry>
        <mesh filename="package://elfin_description/meshes/elfin10/elfin_link1.STL"/>
      </geometry>
      <material name="">
        <color rgba="1 1 1 1"/>
      </material>
    </visual>
    <collision>
      <origin rpy="0 0 0" xyz="0 0 0"/>
      <geometry>
        <mesh filename="package://elfin_description/meshes/elfin10/elfin_link1.STL"/>
      </geometry>
    </collision>
  </link>
  <joint name="elfin_joint1" type="revolute">
    <origin rpy="0 0 0" xyz="0 0 0.0794"/>
    <parent link="elfin_base"/>
    <child link="elfin_link1"/>
    <axis xyz="0 0 1"/>
    <limit effort="104" lower="-3.14" upper="3.14" velocity="1.57"/>
  </joint>
  <link name="elfin_link2">
    <inertial>
      <origin rpy="0 0 0" xyz="6.76058799303212E-06 -0.042999875819422 0.209938025941438"/>
      <mass value="1.67177851395468"/>
      <inertia ixx="0.0439485446845192" ixy="-4.52807636811865E-07" ixz="-7.43339382852812E-06" iyy="0.0454864353408678" iyz="-0.0016627192868139" izz="0.00419718886154138"/>
    </inertial>
    <visual>
      <origin rpy="0 0 0" xyz="0 0 0"/>
      <geometry>
        <mesh filename="package://elfin_description/meshes/elfin10/elfin_link2.STL"/>
      </geometry>
      <material name="">
        <color rgba="0.501960784313725 0.501960784313725 0.501960784313725 1"/>
      </material>
    </visual>
    <collision>
      <origin rpy="0 0 0" xyz="0 0 0"/>
      <geometry>
        <mesh filename="package://elfin_description/meshes/elfin10/elfin_link2.STL"/>
      </geometry>
    </collision>
  </link>
  <joint name="elfin_joint2" type="revolute">
    <origin rpy="0 0 0" xyz="0 -0.1006 0.1806"/>
    <parent link="elfin_link1"/>
    <child link="elfin_link2"/>
    <axis xyz="0 -1 0"/>
    <limit effort="104" lower="-2.35" upper="2.35" velocity="1.57"/>
  </joint>
  <link name="elfin_link3">
    <inertial>
      <origin rpy="0 0 0" xyz="-2.62996059291557E-05 0.0490394097580479 0.052175062906049"/>
      <mass value="2.52843012692852"/>
      <inertia ixx="0.0139637252708319" ixy="2.19112531145417E-06" ixz="-3.30099393077099E-06" iyy="0.0122350897234042" iyz="-0.00342609019238153" izz="0.00648764255835148"/>
    </inertial>
    <visual>
      <origin rpy="0 0 0" xyz="0 0 0"/>
      <geometry>
        <mesh filename="package://elfin_description/meshes/elfin10/elfin_link3.STL"/>
      </geometry>
      <material name="">
        <color rgba="1 1 1 1"/>
      </material>
    </visual>
    <collision>
      <origin rpy="0 0 0" xyz="0 0 0"/>
      <geometry>
        <mesh filename="package://elfin_description/meshes/elfin10/elfin_link3.STL"/>
      </geometry>
    </collision>
  </link>
  <joint name="elfin_joint3" type="revolute">
    <origin rpy="0 0 0" xyz="0 0.0296 0.48"/>
    <parent link="elfin_link2"/>
    <child link="elfin_link3"/>
    <axis xyz="0 1 0"/>
    <limit effort="69" lower="-2.61" upper="2.61" velocity="1.57"/>
  </joint>
  <link name="elfin_link4">
    <inertial>
      <origin rpy="0 0 0" xyz="7.16230692529086E-06 -0.0655290443401757 0.159896102785824"/>
      <mass value="0.77472632829127"/>
      <inertia ixx="0.0123453730002939" ixy="5.3931985013663E-08" ixz="6.96327319489119E-07" iyy="0.0114525775167076" iyz="0.00266638141144531" izz="0.00252781952691956"/>
    </inertial>
    <visual>
      <origin rpy="0 0 0" xyz="0 0 0"/>
      <geometry>
        <mesh filename="package://elfin_description/meshes/elfin10/elfin_link4.STL"/>
      </geometry>
      <material name="">
        <color rgba="0.501960784313725 0.501960784313725 0.501960784313725 1"/>
      </material>
    </visual>
    <collision>
      <origin rpy="0 0 0" xyz="0 0 0"/>
      <geometry>
        <mesh filename="package://elfin_description/meshes/elfin10/elfin_link4.STL"/>
      </geometry>
    </collision>
  </link>
  <joint name="elfin_joint4" type="revolute">
    <origin rpy="0 0 0" xyz="0 0.071 0.145"/>
    <parent link="elfin_link3"/>
    <child link="elfin_link4"/>
    <axis xyz="0 0 1"/>
    <limit effort="69" lower="-3.14" upper="3.14" velocity="1.57"/>
  </joint>
  <link name="elfin_link5">
    <inertial>
      <origin rpy="0 0 0" xyz="7.94801868796714E-06 0.0434911461018785 0.0377663456063138"/>
      <mass value="1.07924103919594"/>
      <inertia ixx="0.0034729009457966" ixy="-5.52196757851043E-07" ixz="-1.81605217014424E-07" iyy="0.00288839322873982" iyz="-0.00085933122800016" izz="0.00165138766321844"/>
    </inertial>
    <visual>
      <origin rpy="0 0 0" xyz="0 0 0"/>
      <geometry>
        <mesh filename="package://elfin_description/meshes/elfin10/elfin_link5.STL"/>
      </geometry>
      <material name="">
        <color rgba="1 1 1 1"/>
      </material>
    </visual>
    <collision>
      <origin rpy="0 0 0" xyz="0 0 0"/>
      <geometry>
        <mesh filename="package://elfin_description/meshes/elfin10/elfin_link5.STL"/>
      </geometry>
    </collision>
  </link>
  <joint name="elfin_joint5" type="revolute">
    <origin rpy="0 0 0" xyz="0 -0.061 0.375"/>
    <parent link="elfin_link4"/>
    <child link="elfin_link5"/>
    <axis xyz="0 1 0"/>
    <limit effort="34" lower="-2.56" upper="2.56" velocity="1.57"/>
  </joint>
  <link name="elfin_link6">
    <inertial>
      <origin rpy="0 0 0" xyz="-9.26612634280175E-05 -0.0081738605677491 0.0354638117456494"/>
      <mass value="0.119882706389467"/>
      <inertia ixx="8.35693202355099E-05" ixy="-2.08449849387281E-07" ixz="-1.2465765267456E-09" iyy="8.12022606285257E-05" iyz="-2.22337351477352E-06" izz="0.0001400999122568"/>
    </inertial>
    <visual>
      <origin rpy="0 0 0" xyz="0 0 0"/>
      <geometry>
        <mesh filename="package://elfin_description/meshes/elfin10/elfin_link6.STL"/>
      </geometry>
      <material name="">
        <color rgba="1 1 1 1"/>
      </material>
    </visual>
    <collision>
      <origin rpy="0 0 0" xyz="0 0 0"/>
      <geometry>
        <mesh filename="package://elfin_description/meshes/elfin10/elfin_link6.STL"/>
      </geometry>
    </collision>
  </link>
  <joint name="elfin_joint6" type="revolute">
    <origin rpy="0 0 0" xyz="0 0.061 0.109"/>
    <parent link="elfin_link5"/>
    <child link="elfin_link6"/>
    <axis xyz="0 0 1"/>
    <limit effort="34" lower="-3.14" upper="3.14" velocity="1.57"/>
  </joint>
  <link name="elfin_end_link"/>
  <joint name="elfin_end_joint" type="fixed">
    <origin rpy="0 0 0" xyz="0 0 0.059"/>
    <parent link="elfin_link6"/>
    <child link="elfin_end_link"/>
  </joint>
  <link name="elfin_dummy_gripper"/>
  <joint name="elfin_dummy_joint" type="fixed">
    <origin rpy="-1.57079632679 -1.57079632679 0" xyz="0 0.109 0"/>
    <parent link="elfin_link6"/>
    <child link="elfin_dummy_gripper"/>
  </joint>
</robot>

